{"uuid": "fc795075-ce3f-4e4c-932e-80933cb64274", "befores": [{"name": "common_driver", "status": "broken", "statusDetails": {"message": "selenium.common.exceptions.WebDriverException: Message: An unknown server-side error occurred while processing the command. Original error: Error executing adbExec. Original error: 'Command ''C:\\\\Program Files (x86)\\\\Android\\\\android-sdk\\\\platform-tools\\\\adb.exe' -P 5037 -s D5F7N18327001530 shell pm install -g /data/local/tmp/appium_cache/7c30ec5f0f993ec5accfb84873e85dc5147fdf0c.apk' exited with code 1'; Command output: Failure [INSTALL_FAILED_ABORTED: User rejected permissions]\r\n\nStacktrace:\nUnknownError: An unknown server-side error occurred while processing the command. Original error: Error executing adbExec. Original error: 'Command ''C:\\\\Program Files (x86)\\\\Android\\\\android-sdk\\\\platform-tools\\\\adb.exe' -P 5037 -s D5F7N18327001530 shell pm install -g /data/local/tmp/appium_cache/7c30ec5f0f993ec5accfb84873e85dc5147fdf0c.apk' exited with code 1'; Command output: Failure [INSTALL_FAILED_ABORTED: User rejected permissions]\r\n\n    at getResponseForW3CError (C:\\Users\\YM520\\AppData\\Roaming\\npm\\node_modules\\appium\\node_modules\\appium-base-driver\\lib\\protocol\\errors.js:804:9)\n    at asyncHandler (C:\\Users\\YM520\\AppData\\Roaming\\npm\\node_modules\\appium\\node_modules\\appium-base-driver\\lib\\protocol\\protocol.js:380:37)\n", "trace": "  File \"C:\\python3.8\\lib\\site-packages\\pluggy\\_callers.py\", line 80, in _multicall\n    res = hook_impl.function(*args)\n  File \"C:\\python3.8\\lib\\site-packages\\_pytest\\fixtures.py\", line 1123, in pytest_fixture_setup\n    result = call_fixture_func(fixturefunc, request, kwargs)\n  File \"C:\\python3.8\\lib\\site-packages\\_pytest\\fixtures.py\", line 895, in call_fixture_func\n    fixture_result = next(generator)\n  File \"C:\\study\\pythonT\\pyAppium-master\\testcase\\conftest.py\", line 32, in common_driver\n    driver = base_driver.base_driver()\n  File \"C:\\study\\pythonT\\pyAppium-master\\common\\base_driver.py\", line 50, in base_driver\n    driver = webdriver.Remote(f\"http://127.0.0.1:{self.device_info['server_port']}/wd/hub\",\n  File \"C:\\python3.8\\lib\\site-packages\\appium\\webdriver\\webdriver.py\", line 257, in __init__\n    super().__init__(\n  File \"C:\\python3.8\\lib\\site-packages\\selenium\\webdriver\\remote\\webdriver.py\", line 206, in __init__\n    self.start_session(capabilities)\n  File \"C:\\python3.8\\lib\\site-packages\\appium\\webdriver\\webdriver.py\", line 346, in start_session\n    response = self.execute(RemoteCommand.NEW_SESSION, w3c_caps)\n  File \"C:\\python3.8\\lib\\site-packages\\selenium\\webdriver\\remote\\webdriver.py\", line 345, in execute\n    self.error_handler.check_response(response)\n  File \"C:\\python3.8\\lib\\site-packages\\selenium\\webdriver\\remote\\errorhandler.py\", line 229, in check_response\n    raise exception_class(message, screen, stacktrace)\n"}, "start": 1699501114918, "stop": 1699501184885}], "start": 1699501114918, "stop": 1699501185173}