{"uuid": "a1f81f28-198c-412e-97f5-73fb1a969eee", "befores": [{"name": "common_driver", "status": "broken", "statusDetails": {"message": "selenium.common.exceptions.WebDriverException: Message: An unknown server-side error occurred while processing the command. Original error: Error executing adbExec. Original error: 'Command ''C:\\\\Program Files (x86)\\\\Android\\\\android-sdk\\\\platform-tools\\\\adb.exe' -P 5037 -s D5F0218710007612 shell pm install /data/local/tmp/appium_cache/4a3611f83607e4a76c33e4d83ef4a4b6e0b619a6.apk' timed out after 90000ms'. Try to increase the 90000ms adb execution timeout represented by 'androidInstallTimeout' capability\n\n", "trace": "  File \"C:\\python3.8\\lib\\site-packages\\pluggy\\callers.py\", line 187, in _multicall\n    res = hook_impl.function(*args)\n  File \"C:\\python3.8\\lib\\site-packages\\_pytest\\fixtures.py\", line 1123, in pytest_fixture_setup\n    result = call_fixture_func(fixturefunc, request, kwargs)\n  File \"C:\\python3.8\\lib\\site-packages\\_pytest\\fixtures.py\", line 895, in call_fixture_func\n    fixture_result = next(generator)\n  File \"C:\\study\\pythonT\\pyAppium-master\\testcase\\conftest.py\", line 32, in common_driver\n    driver = base_driver.base_driver()\n  File \"C:\\study\\pythonT\\pyAppium-master\\common\\base_driver.py\", line 52, in base_driver\n    driver = webdriver.Remote(f\"http://127.0.0.1:{self.device_info['server_port']}/wd/hub\",\n  File \"C:\\python3.8\\lib\\site-packages\\appium\\webdriver\\webdriver.py\", line 147, in __init__\n    super(WebDriver, self).__init__(\n  File \"C:\\python3.8\\lib\\site-packages\\selenium\\webdriver\\remote\\webdriver.py\", line 157, in __init__\n    self.start_session(capabilities, browser_profile)\n  File \"C:\\python3.8\\lib\\site-packages\\appium\\webdriver\\webdriver.py\", line 227, in start_session\n    response = self.execute(RemoteCommand.NEW_SESSION, parameters)\n  File \"C:\\python3.8\\lib\\site-packages\\selenium\\webdriver\\remote\\webdriver.py\", line 321, in execute\n    self.error_handler.check_response(response)\n  File \"C:\\python3.8\\lib\\site-packages\\selenium\\webdriver\\remote\\errorhandler.py\", line 242, in check_response\n    raise exception_class(message, screen, stacktrace)\n"}, "start": 1699531890798, "stop": 1699531983921}], "start": 1699531890798, "stop": 1699531984523}