{"uuid": "cd53c198-9e93-4b5c-b8f1-531d4eedf6af", "befores": [{"name": "common_driver", "status": "passed", "start": 1698074030681, "stop": 1698074062687}], "afters": [{"name": "common_driver::0", "status": "broken", "statusDetails": {"message": "selenium.common.exceptions.WebDriverException: Message: An unknown server-side error occurred while processing the command. Original error: Error executing adbExec. Original error: 'Command ''C:\\\\Program Files (x86)\\\\Android\\\\android-sdk\\\\platform-tools\\\\adb.exe' -P 5037 -s T9Y0221C09002076 shell am force-stop \"'com.xkw.client'\"' exited with code 1'; Command output: error: device 'T9Y0221C09002076' not found\r\n\nStacktrace:\nUnknownError: An unknown server-side error occurred while processing the command. Original error: Error executing adbExec. Original error: 'Command ''C:\\\\Program Files (x86)\\\\Android\\\\android-sdk\\\\platform-tools\\\\adb.exe' -P 5037 -s T9Y0221C09002076 shell am force-stop \"'com.xkw.client'\"' exited with code 1'; Command output: error: device 'T9Y0221C09002076' not found\r\n\n    at getResponseForW3CError (C:\\Users\\YM520\\AppData\\Roaming\\npm\\node_modules\\appium\\node_modules\\appium-base-driver\\lib\\protocol\\errors.js:804:9)\n    at asyncHandler (C:\\Users\\YM520\\AppData\\Roaming\\npm\\node_modules\\appium\\node_modules\\appium-base-driver\\lib\\protocol\\protocol.js:380:37)\n", "trace": "  File \"C:\\python3.8\\lib\\site-packages\\allure_commons\\_allure.py\", line 221, in __call__\n    return self._fixture_function(*args, **kwargs)\n  File \"C:\\python3.8\\lib\\site-packages\\_pytest\\fixtures.py\", line 911, in _teardown_yield_fixture\n    next(it)\n  File \"C:\\study\\pythonT\\pyAppium-master\\testcase\\conftest.py\", line 35, in common_driver\n    driver.close_app()\n  File \"C:\\python3.8\\lib\\site-packages\\appium\\webdriver\\extensions\\applications.py\", line 178, in close_app\n    self.execute(Command.CLOSE_APP)\n  File \"C:\\python3.8\\lib\\site-packages\\selenium\\webdriver\\remote\\webdriver.py\", line 345, in execute\n    self.error_handler.check_response(response)\n  File \"C:\\python3.8\\lib\\site-packages\\appium\\webdriver\\errorhandler.py\", line 122, in check_response\n    raise exception_class(msg=message, stacktrace=format_stacktrace(stacktrace))\n"}, "start": 1698074165980, "stop": 1698074167101}], "start": 1698074030681, "stop": 1698074167101}