{"uuid": "5bc027dc-b43f-40ba-9bf5-bc205ddb2afd", "befores": [{"name": "common_driver", "status": "broken", "statusDetails": {"message": "selenium.common.exceptions.WebDriverException: Message: An unknown server-side error occurred while processing the command. Original error: The instrumentation process cannot be initialized. Make sure the application under test does not crash and investigate the logcat output.\nStacktrace:\nUnknownError: An unknown server-side error occurred while processing the command. Original error: The instrumentation process cannot be initialized. Make sure the application under test does not crash and investigate the logcat output.\n    at getResponseForW3CError (C:\\Users\\YM520\\AppData\\Roaming\\npm\\node_modules\\appium\\node_modules\\appium-base-driver\\lib\\protocol\\errors.js:804:9)\n    at asyncHandler (C:\\Users\\YM520\\AppData\\Roaming\\npm\\node_modules\\appium\\node_modules\\appium-base-driver\\lib\\protocol\\protocol.js:380:37)\n", "trace": "  File \"C:\\python3.8\\lib\\site-packages\\pluggy\\_callers.py\", line 80, in _multicall\n    res = hook_impl.function(*args)\n  File \"C:\\python3.8\\lib\\site-packages\\_pytest\\fixtures.py\", line 1123, in pytest_fixture_setup\n    result = call_fixture_func(fixturefunc, request, kwargs)\n  File \"C:\\python3.8\\lib\\site-packages\\_pytest\\fixtures.py\", line 895, in call_fixture_func\n    fixture_result = next(generator)\n  File \"C:\\study\\pythonT\\pyAppium-master\\testcase\\conftest.py\", line 32, in common_driver\n    driver = base_driver.base_driver()\n  File \"C:\\study\\pythonT\\pyAppium-master\\common\\base_driver.py\", line 50, in base_driver\n    driver = webdriver.Remote(f\"http://127.0.0.1:{self.device_info['server_port']}/wd/hub\",\n  File \"C:\\python3.8\\lib\\site-packages\\appium\\webdriver\\webdriver.py\", line 257, in __init__\n    super().__init__(\n  File \"C:\\python3.8\\lib\\site-packages\\selenium\\webdriver\\remote\\webdriver.py\", line 206, in __init__\n    self.start_session(capabilities)\n  File \"C:\\python3.8\\lib\\site-packages\\appium\\webdriver\\webdriver.py\", line 346, in start_session\n    response = self.execute(RemoteCommand.NEW_SESSION, w3c_caps)\n  File \"C:\\python3.8\\lib\\site-packages\\selenium\\webdriver\\remote\\webdriver.py\", line 345, in execute\n    self.error_handler.check_response(response)\n  File \"C:\\python3.8\\lib\\site-packages\\selenium\\webdriver\\remote\\errorhandler.py\", line 229, in check_response\n    raise exception_class(message, screen, stacktrace)\n"}, "start": 1699510434131, "stop": 1699510467047}], "start": 1699510434131, "stop": 1699510467338}